2024-06-04 21:18:32,211 INFO    StreamThr :534 [internal.py:wandb_internal():86] W&B internal server running at pid: 534, started at: 2024-06-04 21:18:32.210738
2024-06-04 21:18:32,212 DEBUG   HandlerThread:534 [handler.py:handle_request():146] handle_request: status
2024-06-04 21:18:37,213 DEBUG   HandlerThread:534 [handler.py:handle_request():146] handle_request: status_report
2024-06-04 21:18:37,213 INFO    WriterThread:534 [datastore.py:open_for_write():87] open: /data/khullar/Desktop/s4/s4/wandb/run-20240604_211812-uk9xu5un/run-uk9xu5un.wandb
2024-06-04 21:18:42,648 DEBUG   HandlerThread:534 [handler.py:handle_request():146] handle_request: status_report
2024-06-04 21:18:45,129 DEBUG   SenderThread:534 [sender.py:send():382] send: header
2024-06-04 21:18:45,426 DEBUG   SenderThread:534 [sender.py:send():382] send: run
2024-06-04 21:18:50,320 DEBUG   HandlerThread:534 [handler.py:handle_request():146] handle_request: keepalive
2024-06-04 21:18:55,321 DEBUG   HandlerThread:534 [handler.py:handle_request():146] handle_request: keepalive
2024-06-04 21:19:00,312 DEBUG   HandlerThread:534 [handler.py:handle_request():146] handle_request: keepalive
2024-06-04 21:19:03,766 ERROR   SenderThread:534 [internal_api.py:execute():373] 400 response executing GraphQL.
2024-06-04 21:19:03,766 ERROR   SenderThread:534 [internal_api.py:execute():374] {"errors":[{"message":"run config cannot exceed 15 MB","path":["upsertBucket"]}],"data":{"upsertBucket":null}}
2024-06-04 21:19:03,767 ERROR   SenderThread:534 [sender.py:send_run():987] run config cannot exceed 15 MB (Error 400: Bad Request)
Traceback (most recent call last):
  File "/usr/local/lib/python3.11/site-packages/wandb/apis/normalize.py", line 41, in wrapper
    return func(*args, **kwargs)
           ^^^^^^^^^^^^^^^^^^^^^
  File "/usr/local/lib/python3.11/site-packages/wandb/sdk/internal/internal_api.py", line 2216, in upsert_run
    response = self.gql(
               ^^^^^^^^^
  File "/usr/local/lib/python3.11/site-packages/wandb/sdk/internal/internal_api.py", line 341, in gql
    ret = self._retry_gql(
          ^^^^^^^^^^^^^^^^
  File "/usr/local/lib/python3.11/site-packages/wandb/sdk/lib/retry.py", line 131, in __call__
    result = self._call_fn(*args, **kwargs)
             ^^^^^^^^^^^^^^^^^^^^^^^^^^^^^^
  File "/usr/local/lib/python3.11/site-packages/wandb/sdk/internal/internal_api.py", line 369, in execute
    return self.client.execute(*args, **kwargs)  # type: ignore
           ^^^^^^^^^^^^^^^^^^^^^^^^^^^^^^^^^^^^
  File "/usr/local/lib/python3.11/site-packages/wandb/vendor/gql-0.2.0/wandb_gql/client.py", line 52, in execute
    result = self._get_result(document, *args, **kwargs)
             ^^^^^^^^^^^^^^^^^^^^^^^^^^^^^^^^^^^^^^^^^^^
  File "/usr/local/lib/python3.11/site-packages/wandb/vendor/gql-0.2.0/wandb_gql/client.py", line 60, in _get_result
    return self.transport.execute(document, *args, **kwargs)
           ^^^^^^^^^^^^^^^^^^^^^^^^^^^^^^^^^^^^^^^^^^^^^^^^^
  File "/usr/local/lib/python3.11/site-packages/wandb/sdk/lib/gql_request.py", line 59, in execute
    request.raise_for_status()
  File "/usr/local/lib/python3.11/site-packages/requests/models.py", line 1021, in raise_for_status
    raise HTTPError(http_error_msg, response=self)
requests.exceptions.HTTPError: 400 Client Error: Bad Request for url: https://api.wandb.ai/graphql

During handling of the above exception, another exception occurred:

Traceback (most recent call last):
  File "/usr/local/lib/python3.11/site-packages/wandb/sdk/internal/sender.py", line 985, in send_run
    self._init_run(run, config_value_dict)
  File "/usr/local/lib/python3.11/site-packages/wandb/sdk/internal/sender.py", line 1027, in _init_run
    server_run, inserted, server_messages = self._api.upsert_run(
                                            ^^^^^^^^^^^^^^^^^^^^^
  File "/usr/local/lib/python3.11/site-packages/wandb/apis/normalize.py", line 51, in wrapper
    raise CommError(message, error)
wandb.errors.CommError: run config cannot exceed 15 MB (Error 400: Bad Request)
2024-06-04 21:19:03,786 DEBUG   HandlerThread:534 [handler.py:handle_request():146] handle_request: status_report
2024-06-04 21:19:04,233 DEBUG   HandlerThread:534 [handler.py:handle_request():146] handle_request: shutdown
2024-06-04 21:19:04,234 INFO    HandlerThread:534 [handler.py:finish():869] shutting down handler
2024-06-04 21:19:04,786 INFO    SenderThread:534 [sender.py:finish():1572] shutting down sender
2024-06-04 21:19:04,786 INFO    WriterThread:534 [datastore.py:close():296] close: /data/khullar/Desktop/s4/s4/wandb/run-20240604_211812-uk9xu5un/run-uk9xu5un.wandb
